<?xml version="1.0" encoding="utf-8"?>
<!-- =================================================================================== -->
<!-- |    This document was autogenerated by xacro from simple_agv.xacro               | -->
<!-- |    EDITING THIS FILE BY HAND IS NOT RECOMMENDED                                 | -->
<!-- =================================================================================== -->
<!-- ===== Initial differential robot URDF =====-->
<!-- Note: This is only for testing pourpuses of the
CAN communication programs we develop.-->
<robot name="simple_agv">
  <!--Note: The direction should be signaled with as (1 || -1) -->
  <!--Note: The direction should be signaled with as (1 || -1) -->
  <!-- === PARTS ONLY === -->
  <!-- = Transmission = -->
  <!--Note: I use "*" as a separator -->
  <!-- <xacro:macro name="transmission_block" params="joint_name *side *direction">
    
  </xacro:macro> -->
  <!-- === Link declaration === -->
  <!-- Base link -->
  <link name="map">
    <pose>0 0 0 0 0 0</pose>
  </link>
  <!-- Simple link definition-->
  <!-- I'll use chassis as my root link-->
  <!-- Note: The origin is relative to the link.
        it'll usually be 0, because displacement
        will happen on the Joint-->
  <link name="chassis">
    <visual>
      <geometry>
        <box size="0.65 0.5 0.3"/>
      </geometry>
      <origin xyz="0 0 0.3"/>
      <material name="white">
        <color rgba="0 0 1 1"/>
      </material>
    </visual>
  </link>
  <!-- === Joint definition === -->
  <!-- Reference frame -->
  <joint name="map_to_chassis" type="fixed">
    <parent link="map"/>
    <child link="chassis"/>
  </joint>
  <!-- Link (physical part)-->
  <link name="wheel_right">
    <visual>
      <!-- Shape -->
      <geometry>
        <cylinder length="0.1" radius="0.15"/>
      </geometry>
      <!-- Origin relative to the link's joint -->
      <origin rpy="1.57079632679 0 0" xyz="0 0 0"/>
      <material name="black">
        <color rgba="0 0 0 1"/>
      </material>
    </visual>
  </link>
  <!-- Joint (connection between links) -->
  <joint name="joint_wheel_right" type="continuous">
    <parent link="chassis"/>
    <child link="wheel_right"/>
    <origin xyz="0 0.325 0.15"/>
    <!-- Axis rotation-->
    <axis xyz="0 1 0"/>
    <!-- rpy="0 0 0 -->
    <!-- Joint limits (Newtons) (rad/s)-->
    <limit effort="50" velocity="20"/>
  </joint>
  <!-- Transmission -->
  <transmission name="trans_right">
    <!-- Type -->
    <type>transmission_interface/SimpleTransmission</type>
    <!-- Joint -->
    <joint name="joint_wheel_right">
      <hardwareInterface> hardware_interface/EffortJointInterface </hardwareInterface>
    </joint>
    <!-- Actuator -->
    <actuator name="motor_right">
      <hardwareInterface>hardware_interface/EffortJointInterface</hardwareInterface>
      <mechanicalReduction>1</mechanicalReduction>
    </actuator>
  </transmission>
  <!-- Link (physical part)-->
  <link name="wheel_left">
    <visual>
      <!-- Shape -->
      <geometry>
        <cylinder length="0.1" radius="0.15"/>
      </geometry>
      <!-- Origin relative to the link's joint -->
      <origin rpy="1.57079632679 0 0" xyz="0 0 0"/>
      <material name="black">
        <color rgba="0 0 0 1"/>
      </material>
    </visual>
  </link>
  <!-- Joint (connection between links) -->
  <joint name="joint_wheel_left" type="continuous">
    <parent link="chassis"/>
    <child link="wheel_left"/>
    <origin xyz="0 -0.325 0.15"/>
    <!-- Axis rotation-->
    <axis xyz="0 1 0"/>
    <!-- rpy="0 0 0 -->
    <!-- Joint limits (Newtons) (rad/s)-->
    <limit effort="50" velocity="20"/>
  </joint>
  <!-- Transmission -->
  <transmission name="trans_left">
    <!-- Type -->
    <type>transmission_interface/SimpleTransmission</type>
    <!-- Joint -->
    <joint name="joint_wheel_left">
      <hardwareInterface> hardware_interface/EffortJointInterface </hardwareInterface>
    </joint>
    <!-- Actuator -->
    <actuator name="motor_left">
      <hardwareInterface>hardware_interface/EffortJointInterface</hardwareInterface>
      <mechanicalReduction>1</mechanicalReduction>
    </actuator>
  </transmission>
  <!-- === Gazebo Plugin === -->
  <!-- <gazebo>
        <plugin name="gazebo_ros_control" filename="libgazebo_ros_control.so">
            <robotNamespace>/drivetrain</robotNamespace>
        </plugin>
    </gazebo> -->
</robot>

